<?xml version="1.0" ?>
<!-- =================================================================================== -->
<!-- |    This document was autogenerated by xacro from robot.urdf.xacro               | -->
<!-- |    EDITING THIS FILE BY HAND IS NOT RECOMMENDED                                 | -->
<!-- =================================================================================== -->
<robot name="myrobot">
  <material name="Orange">
    <color rgba="1 0.5 0 1"/>
  </material>
  <material name="yellow">
    <color rgba="1 1 0 1"/>
  </material>
  <material name="black">
    <color rgba="1 1 1 1"/>
  </material>
  <link name="base_link">
    <visual>
      <origin rpy="0 0 0" xyz="0 0 0.45"/>
      <geometry>
        <box size="0.8 0.5 0.9"/>
      </geometry>
      <material name="Orange"/>
    </visual>
    <collision>
      <origin rpy="0 0 0" xyz="0 0 0.45"/>
      <geometry>
        <box size="0.8 0.5 0.9"/>
      </geometry>
    </collision>
    <inertial>
      <origin rpy="0 0 0" xyz="0 0 0"/>
      <mass value="0.3"/>
      <inertia ixx="0.0265" ixy="0.0" ixz="0.0" iyy="0.036250000000000004" iyz="0.0" izz="0.022250000000000002"/>
    </inertial>
  </link>
  <gazebo reference="base_link">
    <material>Gazebo/Orange</material>
  </gazebo>
  <link name="laser_link">
    <visual>
      <origin rpy="0 0 0" xyz="0 0 0"/>
      <geometry>
        <cylinder length="0.1" radius="0.2"/>
      </geometry>
      <material name="yellow"/>
    </visual>
  </link>
  <gazebo reference="laser_link">
    <material>Gazebo/Yellow</material>
  </gazebo>
  <joint name="base_laser_joint" type="fixed">
    <origin rpy="0 0 0" xyz="0 0 0.9500000000000001"/>
    <parent link="base_link"/>
    <child link="laser_link"/>
  </joint>
  <link name="left_wheel">
    <visual>
      <origin xyz="0 0 0"/>
      <geometry>
        <cylinder length="0.1" radius="0.2"/>
      </geometry>
      <material name="black"/>
    </visual>
  </link>
  <joint name="left_wheel_joint" type="continuous">
    <origin rpy="1.5707963267948966 0 0" xyz="-0.30000000000000004 -0.3 0"/>
    <parent link="base_link"/>
    <child link="left_wheel"/>
    <axis xyz="0 0 1"/>
  </joint>
  <link name="right_wheel">
    <visual>
      <origin xyz="0 0 0"/>
      <geometry>
        <cylinder length="0.1" radius="0.2"/>
      </geometry>
      <material name="black"/>
    </visual>
  </link>
  <joint name="right_wheel_joint" type="continuous">
    <origin rpy="1.5707963267948966 0 0" xyz="-0.30000000000000004 0.3 0"/>
    <parent link="base_link"/>
    <child link="right_wheel"/>
    <axis xyz="0 0 1"/>
  </joint>
  <link name="arm1">
    <visual>
      <geometry>
        <box size="0.9 0.05 0.1"/>
      </geometry>
    </visual>
  </link>
  <joint name="arm1_joint" type="continuous">
    <origin rpy="0 0 0" xyz="0 0 0.9"/>
    <parent link="base_link"/>
    <child link="arm1"/>
    <axis xyz="0 0 1"/>
  </joint>
</robot>
